Workbook

Sheet ENERO
A1: Claim amount | B1: Id | C1: Reference No | D1: Claim Handler | E1: CS Claim No | F1: Assured | G1: Opponent | H1: Vessel | I1: Place of Discharge | J1: Date of Discharge | K1: Surveyorco | L1: Voyage | M1: Summary | N1: Commodity | O1: Date of Loading | P1: TB | Q1: Fecha de Orden | R1: Participation | S1: Comentarios Reunión
A2: 5496.4 | B2: TRASPASADO | C2: PRE-FIS-MSC-2024-01/26-2982 | D2: Thomas Chatterton | E2: CS-2024-01337 | F2: Prize | G2: MSC | H2: MANZANILLO EXPRESS | I2: Hong Kong | J2: 23.01.2024 | K2: Teamhead | L2: 2346W | M2: TEMPERATURE | N2: CHERRIES | O2: 30.12.2023 | P2: 23.01.2026
A3: 57811.9 | B3: TRASPASADO | C3: PRE-FIS-MAE-2024-01/26-2979 | D3: Nicolas Nuñez | E3: CS-2024-01334 | F3: Prize | G3: Maersk | H3: MAERSK EINDHOVEN | I3: Nansha | J3: 04.01.2024 | K3: Teamhead | L3: 348W | M3: TEMPERATURE / INSPECTOR INDICA ORIGEN, POR LO QUE HABRÍA QUE ABORDAR EL CASO PARA QUE SE ENFOQUE EN TEMP. | N3: CHERRIES | O3: 13.12.2023 | P3: 04.01.2026 | S3: 17.04.2024: Hablar con Kelly para que enfoque caso en temperatura. Cuando sea traspasable, pasar a extrajudicial. | T3: Extensión hasta el 4 de mayo

Sheet FEBRERO
A1: Claim amount | B1: Id | C1: Reference No | D1: Claim Handler | E1: CS Claim No | F1: Assured | G1: Opponent | H1: Vessel | I1: Place of Discharge | J1: Date of Discharge | K1: Surveyorco | L1: Voyage | M1: Summary | N1: Commodity | O1: Date of Loading | P1: TB | Q1: Fecha de Orden | R1: Participation | S1: Comentarios Reunión
A2: 19361.54 | B2: SOLICITADO | C2: PRE-FIS-SEA-2025-02/26-3556 | D2: Thomas Chatterton | E2: CS-2024-02123 | F2: Fairtrasa | G2: Seatrade | H2: PACIFIC REEFER | I2: Vlissingen | J2: 29.02.2024 | K2: Fruit Inspection & Consultancy BV | M2: Temperature, 10 días delay | N2: Mangoes | O2: 04.02.2024 | P2: 28.02.2026
A3: 17219.43 | B3: SOLICITADO | C3: PRE-FIS-MSC-2024-02/26-3110 | D3: Nicolás Nuñez | E3: CS-2024-02186 | F3: Prize | G3: MSC | H3: LIMA EXPRESS | I3: Hong Kong | J3: 23.02.2024 | K3: Teamhead | L3: 2350W | M3: Inspector indica condicion de origen, pero termo muestra temp más baja de lo solicitada y retorno en alza. | N3: Plums | O3: 31.01.2024 | P3: 23.02.2026 | S3: 27.06.2024 Caso pasará una vez listo a Thomas para pedir data a MSC y con esa información ver si Kelly cambia visión y de estar limpio se da de baja.
A4: 25482.31 | B4: SOLICITADO | C4: PRE-FIS-MSC-2024-02/26-3108 | D4: Nicolás Nuñez | E4: CS-2024-01868 | F4: Prize | G4: MSC | H4: BUENAVENTURA EXPRESS | I4: Hong Kong | J4: 20.02.2024 | K4: Teamhead | L4: 2349W | M4: Temperatura | N4: Plums | O4: 20.01.2024 | P4: 20.02.2026
A5: 12155.32 | B5: A PRESENTAR | C5: PRE-FIS-MAE-2025-02/26-3411 | D5: Thomas Chatterton | E5: CS-2024-06994 | F5: FRUTAM | G5: Maersk | H5: MAERSK BULAN | I5: Manzanillo | J5: 25.02.2024 | K5: CSM | L5: 405N | M5: Temperature, delay 9 dias | N5: Nectarines | O5: 08.02.2024 | P5: 25.02.2026
A6: 42949.53 | B6: TRASPASADO | C6: PRE-FIS-HLL-2024-02/26-3090 | D6: Thomas Chatterton | E6: CS-2024-02125 | F6: RANCO | G6: Hapag Lloyd | H6: RIO DE JANEIRO EXPRESS | I6: Hai Phòng | J6: 26.02.2024 | K6: AIM Control Group | L6: 2348W | M6: Delay 12 dias app, TT43 dias e indica tiempo desde packing, pero solo fue 3 dias antes del embarque y cosecha 6 dias antes | N6: Cherries | O6: 16.01.2024 | P6: 26.02.2026 | S6: 19.06.2024 (LB) Traspasar una vez listo.
A7: 29376 | B7: SOLICITADO / se realizó seguimiento 06.01.2026 | C7: FIS-CMA-2025-02/26-3843 | D7: Thomas Chatterton | E7: CS-2025-03650 | F7: Pilz-Schindler | G7: CMA CGM | H7: CMA CGM MARSEILLE | I7: London Gateway | J7: 28.02.2025 | K7: MMS | L7: 0RTJSN1MA | M7: Delay (17 días) | N7: Limes | O7: 31.01.2025 | P7: 28.02.2026
A8: 45777.45 | B8: SOLICITADO PLATAFORMA | C8: PRE-FIS-CMA-2024-02/26-3221 | D8: Thomas Chatterton | E8: CS-2024-03135 | F8: Sunshine Peru | G8: CMA CGM | H8: CZECH | I8: Rotterdam | J8: 29.02.2024 | K8: Fruit Inspection & Consultancy BV | L8: 0WCHLS1MA | M8: Delay 9 dias + algunas temperaturas erráticas al comienzo del viaje | N8: Mangoes | O8: 01.02.2024 | P8: 29.02.2026
A9: 81418.16 | B9: SOLICITADO | C9: PRE-FIS-CMA-2024-02/26-3220 | D9: Thomas Chatterton | E9: CS-2024-08337 | F9: Sunshine Peru | G9: CMA CGM | H9: CMA CGM EXCELLENCE | I9: Rotterdam | J9: 28.02.2024 | L9: 0DVI0N1MA | M9: Delay 9 dias | N9: Mangoes | O9: 01.02.2024 | P9: 28.02.2026 | S9: 03.10.2024 Se solicitará a asegurado QC en destino, stuffing
A10: 20502 | B10: SOLICITADO | C10: PRE-FIS-CMA-2024-02/26-3071 | D10: Thomas Chatterton | E10: CS-2024-01867 | F10: Prize | G10: CMA CGM | H10: COSCO SHIPPING BRAZIL | I10: Busan | J10: 16.02.2024 | K10: Hyopsung | L10: 0HCGMW1MA | M10: Delay 16 dias. 80% atribuible transporte y 20% origen | N10: Blueberries | O10: 09.01.2024 | P10: 16.02.2026
A11: 25769.6 | B11: SOLICITADO | C11: PRE-FIS-CMA-2024-02/26-3069 | D11: Thomas Chatterton | E11: CS-2024-01345 | F11: Prize | G11: CMA CGM | H11: COSCO SHIPPING SEINE | I11: Busan | J11: 11.02.2024 | K11: Hyopsung | L11: 0HCGKW1MA | M11: Delay 12 dias. 30% ATRIBUIBLE A ORIGEN | N11: Blueberries | O11: 02.01.2024 | P11: 11.02.2026
A12: 27690 | B12: SOLICITADO | C12: PRE-FIS-CMA-2024-02/26-3063 | D12: Thomas Chatterton | E12: CS-2024-03628 | F12: Prize | G12: CMA CGM | H12: COSCO SHIPPING BRAZIL | I12: Busan | J12: 16.02.2024 | K12: Other | L12: 0HCGKW1MA | M12: Inspector indica no relacionado a transporte.pero está informe de gases que se ven con alzas durante viaje. registro de gases disponible no concuerdqa con solicitado. | N12: Blueberries | O12: 09.01.2024 | P12: 16.02.2026 | S12: 19.06.2024 (LB) Traspasar a Isi cuando esté listo, se presenta directo a Vicente Rios de Liventus
A13: 21453.83 | B13: SOLICITADO | C13: FIS-SLD-2025-02/26-4106 | D13: Thomas Chatterton | E13: CS-2025-03796 | F13: Pilz-Schindler | G13: SeaLand | H13: ZAGOR | I13: Nhava Sheva | J13: 08.02.2025 | K13: Zorro QC | L13: 45R1 | M13: Temperature | N13: Apples | O13: 22.01.2025 | P13: 08.02.2026

Sheet MARZO
A1: Claim amount | B1: Id | C1: Reference No | D1: Claim Handler | E1: CS Claim No | F1: Assured | G1: Opponent | H1: Vessel | I1: Place of Discharge | J1: Date of Discharge | K1: Surveyorco | L1: Voyage | M1: Summary | N1: Commodity | O1: Date of Loading | P1: TB | Q1: Fecha de Orden | R1: Participation | S1: Comentarios Reunión
A2: 18463.61 | B2: PRESENTAR | C2: PRE-FIS/TRV-HLL-2025-03/26-3961 | D2: Nicolás Nuñez | E2: CS-2025-02543 | F2: Tropicales del Valle S.A. | G2: Hapag Lloyd | H2: ACASTOS | I2: Antwerpen | J2: 01.03.2025 | K2: Fruit Inspection & Consultancy BV | M2: Delay | N2: Pineapples | O2: 03.02.2025 | P2: 01.03.2026
A3: 8021.47 | B3: SOLICITADO | C3: PRE-FIS-MSC-2024-03/26-3103 | D3: Matias Farcuh | E3: CS-2024-03074 | F3: Prize | G3: MSC | H3: BUENOS AIRES EXPRESS | I3: Hong Kong | J3: 15.03.2024 | K3: Teamhead | L3: 2352W | M3: Temperatura / DELAY 6 DIAS POL/ | N3: Nectarines | O3: 20.02.2024 | P3: 15.03.2026 | S3: 06.02.2025 TRASPASAR A MATIAS UNA VEZ LISTO
A4: 29083.05 | B4: SOLICITADO | C4: PRE-FIS-MAE-2024-03/26-3101 | D4: Nicolás Nuñez | E4: CS-2024-02527 | F4: Prize | G4: Maersk | H4: CAROLINE MAERSK | I4: Hong Kong | J4: 11.03.2024 | K4: Teamhead | L4: 405W | M4: Temperatura | N4: Nectarines | O4: 14.02.2024 | P4: 11.03.2026
A5: 39654.56 | B5: SOLICITADO | C5: PRE-FIS-MSC-2024-03/26-3100 | D5: Matias Farcuh | E5: CS-2024-02429 | F5: Prize | G5: MSC | H5: CAUTIN | I5: Hong Kong | J5: 02.03.2024 | K5: Teamhead | L5: 2351W | M5: Temperatura | N5: Plums | O5: 06.02.2024 | P5: 02.03.2026
A6: 33164.07 | B6: SOLICITADO | C6: PRE-FIS-CMA-2024-03/26-3109 | D6: Nicolás Nuñez | E6: CS-2024-03072 | F6: Prize | G6: CMA CGM | H6: CMA CGM BEIRA | I6: Algeciras | J6: 13.03.2024 | K6: Montalvao | L6: 0LIGFN1MA | M6: Temperatura | N6: Nectarines | O6: 16.02.2024 | P6: 13.03.2026
A7: 60292.66 | B7: SOLICITADO | C7: PRE-FIS-CMA-2024-03/26-3219 | D7: Emely Lambraño | E7: CS-2024-05873 | F7: Sunshine Peru | G7: CMA CGM | H7: CMA CGM BETTER WAYS | I7: Rotterdam | J7: 21.03.2024 | K7: McLeans | L7: 0DVI8N1MA | M7: Temperatura, se ve entre 10 y 11 durante viaje la de retorno y sum entre 9 y 10 y cuando llega a destino temp baja a los 8 grados del setting. | N7: Mangoes | O7: 28.02.2024 | P7: 21.03.2026
A8: 55526.66 | B8: SOLICITADO | C8: PRE-FIS-MAE-2024-03/26-3104 | D8: Nicolás Nuñez | E8: CS-2024-03073 | F8: Prize | G8: Maersk | H8: CORNELIUS MAERSK | I8: Hong Kong | J8: 17.03.2024 | K8: Teamhead | L8: 406W | M8: Temperatura / pérdida total | N8: Nectarines | O8: 21.02.2024 | P8: 17.03.2026
A9: 40519.43 | B9: SOLICITADO | C9: PRE-FIS-CMA-2024-03/26-3218 | D9: Emely Lambraño | E9: CS-2024-03293 | F9: Sunshine Peru | G9: CMA CGM | H9: GUAYAQUIL EXPRESS | I9: Rotterdam | J9: 21.03.2024 | K9: Fruit Inspection & Consultancy BV | L9: 0WCH8N1MA | M9: inspector indica potencialmente no relacionado a tránsito, indica fruta inconsistente como causal delay, que los problemas se pueden haber exacerbado con la demora. | N9: Mangoes | O9: 21.02.2024 | P9: 21.03.2026 | S9: 03.10.2024 Se solicitará a asegurado QC en destino, stuffing y se presenta sin reporte de inspección.
A10: 6199.43 | B10: SOLICITADO | C10: PRE-FIS-MAE-2024-03/26-3157 | D10: Thomas Chatterton | E10: CS-2024-07015 | F10: Vidimport Monterrey | G10: Maersk Line | H10: MAERSK BINTAN | I10: Manzanillo | J10: 14.03.2024 | K10: CMS | L10: 407N | M10: Temperature | N10: Grapes | O10: 21.02.2024 | P10: 14.03.2026
A11: 62394.1 | B11: SOLICITADO / revisar. | C11: PRE-FIS-MAE-2025-03/26-3407 | D11: Nicolás Nuñez | E11: CS-2024-07742 | F11: FRUTAM | G11: Maersk | H11: MAERSK BULAN | I11: Manzanillo | J11: 18.03.2024 | K11: CSM | L11: 405N | N11: Peaches | O11: 08.02.2024 | P11: 18.03.2026
A12: 31600.18 | B12: SOLICITADO | C12: PRE-FIS-MAE-2024-03/26-3293 | D12: Thomas Chatterton | E12: CS-2024-03103 | F12: FRUSAN | G12: Maersk | H12: MAERSK LABERINTO | I12: Hong Kong | J12: 31.03.2024 | K12: Teamhead | L12: 4058W | M12: TEMPERATURE | N12: Plums | O12: 05.03.2024 | P12: 31.03.2026 | S12: Casos Sugar Plums: Los cracks vienen de la condensación dentro de las bolsas por las variaciones (aunque pequeñas) durante el transporte... De repente Kelly puede incorporar ese dato al informe también. Según Frusan es común que condensación causa cracks en los plums....
A13: 21718.49 | B13: SOLICITADO | C13: PRE-FIS-MSC-2024-03/26-3115 | D13: Matias Farcuh | E13: CS-2024-03089 | F13: FRUSAN | G13: MSC | H13: MSC AVNI | I13: Rotterdam | J13: 17.03.2024 | K13: Fruit Inspection & Consultancy BV | L13: NX407R | M13: Temperature | N13: Plums | O13: 17.02.2024 | P13: 17.03.2026
A14: 52790.64 | B14: SOLICITADO | C14: PRE-FIS-MSC-2024-03/26-3068 | D14: Matias Farcuh | E14: CS-2024-03076 | F14: Prize | G14: MSC | H14: MSC YASHI B | I14: Philadelphia | J14: 13.03.2024 | K14: PCCC | L14: NX408R | M14: Registro de gases disponible no concuerda con solicitado. Se indica posible problema de temp, pero no figuran los termos disponibles. | N14: Blueberries | O14: 25.02.2024 | P14: 13.03.2026 | S14: 13.06.2024: Exhibición a future y asignar a Victor Vilches
A15: 5137.33 | B15: SOLICITADO | C15: PRE-FIS-MSC-2024-03/26-3056 | D15: Matias Farcuh | E15: CS-2024-03095 | F15: FRUSAN | G15: MSC | H15: MSC YASHI B | I15: London Gateway | J15: 22.03.2024 | K15: MMS | L15: NX408R | M15: TEMPERATURA, daños por frío, igual daños de origen encontrados.- | N15: Plums | O15: 25.02.2024 | P15: 22.03.2026
A16: 23916.41 | B16: SOLICITADO | C16: PRE-FIS-HLL-2024-03/26-3065 | D16: Thomas Chatterton | E16: CS-2024-02430 | F16: Prize | G16: Hapag Lloyd | H16: SANTOS EXPRESS | I16: Rotterdam | J16: 09.03.2024 | K16: Fruit Inspection & Consultancy BV | L16: 3252N | M16: Delay, registro de gases disponible no concuerdqa con solicitado. | N16: Blueberries | O16: 09.02.2024 | P16: 09.03.2026 | S16: 13.06.2024: Presentar extrajudicialmente cuando sea traspasable (isi martinez)
A17: 121874.26 | B17: SOLICITADO | C17: PRE-FIS-HLL-2024-03/26-3064 | D17: Thomas Chatterton | E17: CS-2024-02427 | F17: Prize | G17: Hapag Lloyd | H17: SANTOS EXPRESS | I17: Rotterdam | J17: 09.03.2024 | K17: Fruit Inspection & Consultancy BV | L17: 3252N | M17: DELAY exaserva condicion de la fruta. | N17: Blueberries | O17: 09.02.2024 | P17: 09.03.2026 | S17: 13.06.2024: Presentar extrajudicial en un futuro con el reporte, ya que no todo el daño es considerado preembarque (también considerar atmosfera). Si lo rechazan, evaluar pasar a judicial.
A18: 21199.5 | B18: SOLICITADO | C18: PRE-FIS-COS-2025-03/26-3554 | D18: Thomas Chatterton | E18: CS-2024-02535 | F18: Fairtrasa | G18: Cosco | H18: SANTOS EXPRESS | I18: Rotterdam | J18: 08.03.2024 | K18: Fruit Inspection & Consultancy BV | M18: Mishandling | P18: 08.03.2026
A19: 20290.82 | B19: SOLICITADO | C19: PRE-FIS-MSC-2024-03/26-3292 | D19: Eduardo Rojas | E19: CS-2024-03102 | F19: FRUSAN | G19: MSC | H19: SEASPAN BRIGHTNESS | I19: Hong Kong | J19: 26.03.2024 | K19: Teamhead | L19: 2402W | M19: TEMPERATURE | N19: Plums | O19: 22.02.2024 | P19: 26.03.2026 | S19: Casos Sugar Plums: Los cracks vienen de la condensación dentro de las bolsas por las variaciones (aunque pequeñas) durante el transporte... De repente Kelly puede incorporar ese dato al informe también. Según Frusan es común que condensación causa cracks en los plums....
A20: 9027.83 | B20: SOLICITADO | C20: PRE-FIS-MSC-2024-03/26-3280 | D20: Eduardo Rojas | E20: CS-2024-03100 | F20: FRUSAN | G20: MSC | H20: SEASPAN BRIGHTNESS | I20: Hong Kong | J20: 26.03.2024 | K20: Teamhead | M20: Temperatura | N20: Plums | O20: 22.02.2024 | P20: 26.03.2026

Sheet ABRIL
A1: Claim amount | B1: Id | C1: Reference No | D1: Claim Handler | E1: CS Claim No | F1: Assured | G1: Opponent | H1: Vessel | I1: Place of Discharge | J1: Date of Discharge | K1: Surveyorco | L1: Voyage | M1: Summary | N1: Commodity | O1: Date of Loading | P1: TB | Q1: Fecha de Orden | R1: Participation | S1: Comentarios Reunión | T1: Itinerario MSC | U1: TT OFRECIDO | V1: TT REAL
A2: 7598.75 | B2: A PRESENTAR | C2: PRE-FIS/TRV-HLL-2025-04/26-3965 | D2: Nicolás Nuñez | E2: CS-2025-05432 | F2: Tropicales del Valle S.A. | G2: Hapag Lloyd | H2: ACASTOS | I2: Antwerpen | J2: 26.04.2025 | K2: Fruit Inspection & Consultancy BV | M2: Delay (11 days) | N2: Pineapples | O2: 01.04.2025 | P2: 26.04.2026
A3: 44439 | B3: SOLICITADO | C3: PRE-FIS-CMA-2024-04/26-3331 | D3: Nicolás Nuñez | E3: CS-2024-07037 | F3: Rio Blanco SpA | G3: CMA CGM | H3: CMA CGM PREGOLIA | I3: Algeciras | J3: 03.04.2024 | M3: Robo de 16 pallets y otros dos destruidos. No se ve signos de manipulación, se debe solicitar pesaje oficial en POL. VGM | N3: Grapes | O3: 11.03.2024 | P3: 03.04.2026
A4: 49371.91 | B4: SOLICITADO | C4: PRE-FIS-SEA-2024-04/26-3216 | D4: Nicolás Nuñez | E4: CS-2024-05874 | F4: Asica Farms SAC | G4: Seatrade | H4: HOOD ISLAND | I4: Vlissingen | J4: 10.04.2024 | K4: Fruit Inspection & Consultancy BV | L4: SR24009 | M4: CA, pero inspector menciona que los niveles de ethanol presente en la fruta eran mínimos. | N4: Avocados | O4: 24.03.2024 | P4: 10.04.2026 | S4: 26.09.2024 Cuando caso esté listo extrajudicial si se consigue data y registro de atmosfera
A5: 41439.55 | B5: SOLICITADO | C5: PRE-FIS-MAE-2025-04/26-3402 | D5: Thomás Chatterton | E5: CS-2024-04109 | F5: Servicios Chilfresh | G5: Maersk | H5: JPO PISCES | I5: San Juan | J5: 10.04.2024 | K5: Other | L5: 411N | M5: Delay por falla en C/T | N5: Grapes | O5: 21.03.2024 | P5: 10.04.2026
A6: 42768.1 | B6: A PRESENTAR | C6: PRE-FIS-ONE-2025-04/26-3410 | D6: Thomás Chatterton | E6: CS-2024-03632 | F6: Monteco / Sun Fresh | G6: ONE | H6: NYK JOANNA | I6: Valparaiso | J6: 08.04.2024 | K6: Crawford, CHL | L6: 0182E | M6: Delay / Temperature | N6: Lemons | O6: 06.02.2024 | P6: 08.04.2026
B7: REVISADO | C7: PRE-FIS-HLL-2026-04/26-4373 | D7: Nicolás Nuñez | E7: CS-2025-04315 | F7: Dutoit Europe B.V. | G7: Hapag Lloyd | H7: ACASTOS | I7: Antwerpen | J7: 25.04.2025 | K7: Fruit Inspection & Consultancy BV | L7: 513N | M7: Temperature | N7: Pineapples | O7: 02.04.2025 | P7: 25.04.2026 | Q7: 25.02.2026

Sheet MAYO
A1: Claim amount | B1: Id | C1: Reference No | D1: Claim Handler | E1: CS Claim No | F1: Assured | G1: Opponent | H1: Vessel | I1: Place of Discharge | J1: Date of Discharge | K1: Surveyorco | L1: Voyage | M1: Status | N1: Summary | O1: Commodity | P1: Date of Loading | Q1: TB
A2: 18657.13 | B2: SOLICITADO | C2: PRE-FIS-CMA-2024-05/26-3179 | D2: Thomas Chatterton | E2: CS-2024-04777 | F2: FRUSAN | G2: CMA CGM | H2: VALPARAISO EXPRESS | I2: Leghorn | J2: 07.05.2024 | K2: Spolidoro | L2: 0WCH0N1MA | M2: Falta AoR, Booking, stuffing, origin, DUS, IVV, SR | N2: Temperature | O2: Pears | P2: 29.03.2024 | Q2: 07.05.2026
A3: 5683.82 | B3: SOLICITADO | C3: PRE-FIS-HLL-2024-05/26-3345 | D3: Thomas Chatterton | E3: CS-2024-04780 | F3: Magna | G3: Hapag Lloyd | H3: SANTOS EXPRESS | I3: Rotterdam | J3: 14.05.2024 | K3: Fruit Inspection & Consultancy BV | L3: 4210N | M3: Falta Payment letter (Adjunta), AoR (Adjunta), DUS, IVV | N3: Inspector indica no relacionado a tránsito/ temperatura irregular claramente en termos | O3: PEARS | P3: 17.04.2024 | Q3: 14.05.2026
A4: 5600 | B4: SOLICITADO / EME | C4: PRE-FIS-ONE-2025-05/26-3408 | D4: Emely Lambraño | E4: CS-2024-05427 | F4: Monteco / Sun Fresh | G4: ONE | H4: NYK ROMULUS | I4: Callao | J4: 18.05.2024 | M4: Falta Subro, AoR, Harvest | N4: Temperature | O4: Apples | P4: 20.04.2024 | Q4: 18.05.2026
B5: CALCULAR LOSS | C5: PRE-FIS-MSC-2025-05/26-3399 | D5: Emely Lambraño | E5: CS-2024-05844 | F5: Green Valley | G5: MSC | H5: MSC NITYA B | I5: Philadelphia | J5: 08.05.2024 | K5: PCCC | L5: NX414R | M5: Falta Subro, AoR, export Invoice, origin certificate, phyto, Harvest, SR, booking | N5: Delay | O5: Grapes | P5: 06.04.2024 | Q5: 08.05.2026
B6: SOLICITADO | C6: PRE-FIS-MAE-2024-05/26-3325 | D6: Emely Lambraño | E6: CS-2024-09639 | F6: Copefrut | G6: Maersk | H6: MAERSK BRANI | I6: Buenaventura | J6: 11.05.2024 | M6: Falta subro, SMV | N6: transportista despacha contenedor a destino distinto debiendo ser El Salvador | O6: Apples | P6: 25.04.2024 | Q6: 11.05.2026
B7: SOLICITADO | C7: PRE-FIS-HLL-2025-05/26-3442 | D7: Emely Lambraño | E7: CS-2024-07010 | F7: Polar Fruit Chile | G7: Hapag Lloyd | H7: AS CLAUDIA | I7: Manzanillo | J7: 07.05.2024 | K7: CSM | L7: 415N | M7: Falta Subro, Final report (No disponible), SMV | N7: Delay (10 días) | O7: Grapes | P7: 07.01.2024 | Q7: 07.05.2026

Sheet JUNIO
A1: Claim amount | B1: Id | C1: Reference No | D1: Claim Handler | E1: CS Claim No | F1: Assured | G1: Opponent | H1: Vessel | I1: Place of Discharge | J1: Date of Discharge | K1: Surveyorco | L1: Voyage | M1: Summary | N1: Commodity | O1: Date of Loading | P1: TB | Q1: Fecha de Orden | R1: Fecha Update | S1: Participation | T1: Comentarios Reunión
A2: 56238.52 | B2: PRESENTAR | C2: PRE-FIS-LAR-2025-06/26-4305 | D2: Thomas | E2: CS-2026-00840 | F2: Frusan | G2: Terrestre | H2: TH LARRAGUIBEL LTDA | I2: ROTTERDAM | K2: Crawford, CHL | N2: Blueberries | P2: 06.06.2026 | Q2: 30.12.2025 | T2: Caso terrestre, se debe reunir costos por contenedor con la naviera y la diferencia del valor de la fruta entre lo que fue y lo que podría haber sido
A3: 19302.31 | B3: SOLICITADO | C3: PRE-FIS-MSC-2025-06/26-3394 | D3: Thomas | E3: CS-2024-05102 | F3: Agrofruta Fresh | G3: MSC | H3: MSC SHREYA B | I3: Rotterdam | J3: 01.06.2024 | K3: Fruit Inspection & Consultancy BV | L3: NX418R | M3: Temperature | N3: Grapes | O3: 27.04.2024 | P3: 01.06.2026
A4: 58899.75 | B4: PRESENTAR | C4: PRE-FIS-ROS-2025-06/26-4304 | D4: Nicolás Núñez | E4: DIRECTO | F4: Exportadora Quelen | G4: Terrestre | H4: MSC LEIGH | I4: Shanghai | J4: 16.12.2025 | K4: Crawford, CHL | L4: 326 | M4: Volcamiento | N4: Cherries | O4: 16.12.2025 | P4: 16.06.2026 | Q4: 17.12.2025
A5: 13493.4 | B5: SOLICITADO | C5: PRE-FIS-MAE-2024-06/26-3349 | D5: Thomas | E5: CS-2024-05865 | F5: Magna | G5: Maersk | H5: MAERSK BOGOR | I5: Rotterdam | J5: 18.06.2024 | K5: Fruit Inspection & Consultancy BV | L5: 420N | M5: Inspector indica causa origen breve problema de temperatura/ termos muetsran problemas de temperatura con un incremento marcado durante un periodo y el resto erráticas. | N5: PEARS | O5: 23.05.2024 | P5: 18.06.2026 | T5: 19.12.2024 CASO SE ASIGNARÁ UNA VEZ LISTO A THOMAS PARA QUE EXHIBAN DATA NO SE USARÁ REPORTE
B6: SOLICITADO | C6: PRE-FIS-MAE-2024-06/26-3339 | D6: Emely Lambraño | E6: CS-2024-07044 | F6: Magna | G6: Maersk | H6: MAERSK BOGOR | I6: Rotterdam | J6: 18.06.2024 | K6: Fruit Inspection & Consultancy BV | L6: 420N | N6: Pears | O6: 22.05.2024 | P6: 18.06.2026
A7: 33383.55 | B7: SOLICITADO | C7: PRE-FIS-MAE-2024-06/26-3164 | D7: Emely Lambraño | E7: CS-2024-05425 | F7: FRUTAM | G7: Maersk Line | H7: JPO PISCES | I7: Buenaventura | J7: 01.06.2024 | K7: ACI | L7: 419N | M7: TEMPERATURE/TRASVASIJE | N7: Pears | O7: 16.05.2024 | P7: 01.06.2026
A8: 12665.93 | B8: SOLICITADO | C8: PRE-FIS-HLL-2024-06/26-3348 | D8: Thomas | E8: CS-2024-05099 | F8: Magna | G8: Hapag Lloyd | H8: GUAYAQUIL EXPRESS | I8: Rotterdam | J8: 01.06.2024 | K8: Fruit Inspection & Consultancy BV | L8: 4212N | M8: Inspector indica causa origen / termos se ven igual que los dos casos anteriores. | N8: PEARS | O8: 02.05.2024 | P8: 01.06.2026 | T8: 19.12.2024 CASO SE ASIGNARÁ UNA VEZ LISTO A THOMAS PARA QUE EXHIBAN DATA NO SE USARÁ REPORTE
A9: 33528.11 | B9: SOLICITADO | C9: PRE-FIS-CMA-2024-06/26-3286 | D9: Nicolás Núñez | E9: CS-2024-05857 | F9: FRUSAN | G9: CMA CGM | H9: COSCO SHIPPING VOLGA | I9: Rotterdam | J9: 21.06.2024 | K9: Fruit Inspection & Consultancy BV | L9: 0WCI0N1MA | M9: TEMPERATURE | N9: APPLES | O9: 24.05.2024 | P9: 21.06.2026 | R9: 20.02.2026
A10: 18163.89 | B10: SOLICITADO | C10: PRE-FIS-CMA-2024-06/26-3294 | D10: Nicolás Núñez | E10: CS-2024-05858 | F10: FRUSAN | G10: CMA CGM | H10: CMA CGM ESTELLE | I10: Rotterdam | J10: 26.06.2024 | K10: Fruit Inspection & Consultancy BV | L10: 0WCI2N1MA | M10: TEMPERATURE | N10: Kiwis | O10: 30.05.2024 | P10: 26.06.2026

Sheet JULIO
A1: Claim amount | B1: Id | C1: Reference No | D1: Claim Handler | E1: CS Claim No | F1: Assured | G1: Opponent | H1: Vessel | I1: Place of Discharge | J1: Date of Discharge | K1: Surveyorco | L1: Voyage | M1: Summary | N1: Commodity | O1: Date of Loading | P1: TB
A2: 20548.5 | B2: SOLICITADO | C2: PRE-FIS-MSC-2026-07/26-4340 | D2: Emely Lambraño | E2: CS-2025-08621 | F2: Itacu Corporation ltda. | G2: MSC | H2: MSC PASSION III | I2: Gioia Tauro | J2: 06.07.2025 | K2: Spolidoro | L2: PH522R | M2: Temperature (and 6 days of delay) | N2: Pineaples | O2: 07.06.2025 | P2: 06.07.2026
A3: 22390.51 | B3: PRESENTAR | C3: PRE-FIS-MSC-2024-07/26-3788 | D3: Nico Nuñez | E3: CS-2024-06993 | F3: Prize | G3: MSC | H3: MSC MAPUTO | I3: Fos-Sur-Mer | J3: 19.07.2024 | K3: McLeans | L3: NX422R | M3: TEMPERATURE | N3: Apples | O3: 02.06.2024 | P3: 19.07.2026
A4: 19358.47 | B4: PRESENTAR | C4: PRE-FIS-MSC-2024-07/26-3215 | D4: Eduardo Rojas | E4: CS-2024-07740 | F4: Lo Garces | G4: MSC | H4: MSC ELMA | I4: Sines | J4: 28.07.2024 | K4: Montalvao | L4: NX423R | M4: Delay 18 dias | N4: Kiwis | O4: 10.06.2024 | P4: 28.07.2026
A5: 24810.33 | B5: REVISAR | C5: PRE-FIS-PIL-2024-07/26-3238 | D5: Thomas | E5: CS-2024-07061 | F5: Rio Maipo | G5: PIL | H5: KOTA SEJARAH | I5: Nhava Sheva | J5: 06.07.2024 | K5: Intertek, IND | L5: 068W | M5: Temperature + DELAY 15 | N5: Apples | O5: 04.05.2024 | P5: 06.07.2026
B6: SOLICITADO | C6: PRE-FIS-MSC-2024-07/26-3327 | D6: Emely Lambraño | E6: CS-2024-07050 | F6: Copefrut | G6: MSC | H6: ANTHEA Y | I6: Port Everglades | J6: 02.07.2024 | K6: PCCC | L6: NX420R | M6: Temperatura y delay, durante transbordo se genera un alza considerable de varios dias | N6: Apples | O6: 18.05.2024 | P6: 02.07.2026

Sheet Solicitudes 
B1: Reference No | C1: Claim Handler | D1: Assured | E1: Solicitud | F1: Fecha de solicitud | G1: Update
B2: FIS-AFR-2025-10/26-3737 | C2: Thomas | D2: AMS EUROPEAN | E2: Claim notice | F2: 12.02.2026 | G2: Se insiste el 08.05.2026 // 28.05.2026 solicitado a inspector
B3: FIS-MAE-2025-03/27-4038 | C3: Thomas Chatterton | D3: Vidaurri el Salvador | E3: Harvest | F3: 18.05.2026 | G3: SOLICITADO nuevamente el 23.06.2026 / se insiste 13.07 / 17.07 envían subro, se insiste por harvest
B4: FIS-MSC-2025-01/27-3911 | C4: Nico Nuñez | D4: Prize | E4: Harvest, Stuffing | F4: 02.06.2026 | G4: SOLICITADO 23.06.2026 / se insiste 10.07
B5: FIS-MSC-2023-04/24-2302 | C5: Matias Farcuh | D5: Geofrut | E5: email claim notice | F5: 15.06.2026 | G5: Solicitada 15.06.2026
B6: FIS-PIL-2025-10/26-3808 | C6: Nico Nuñez | D6: Santa Azul | E6: Harvest, stuffing | F6: 15.06.2026 | G6: SOLICITADO 24.06 / 10.07 se insiste
B7: PRE-FIS-HLL-2026-10/26-4347 | C7: Nico Nuñez | D7: DUTOIT | E7: BL master y AOR | F7: 30.06.2026 | G7: Solicitado 06.07.2026
B8: FIS-CMA-2024-03/26-3109 | C8: Nico Nuñez | D8: Prize | E8: aclaración de la cantidad destruida | F8: 07.07.2026 | G8: Solicitado 10.07.2026
B9: FIS-HLL-2025-01/27-3836 | C9: Thomas Chatterton | D9: Agricom | E9: Reporte TH | F9: 10.07.2026 | G9: Solicitado 10.07.2026
B10: FIS-CMA-2026-11/26-4485 | C10: Nico Nuñez | D10: Tropicales del valle | E10: Staffin o QC en origen | F10: 20.07.2026 | G10: Solicitado 07.08.2026
B11: FIS-MAE-2025-01/27-4169 | C11: Nico Nuñez | D11: Frusan | E11: stuffing | F11: 27.07.2026 | G11: Solicitado 27.07.2026
B12: FIS-HLL-2026-02/28-4562 | C12: Thomas | D12: Quelen | E12: Reporte TH | F12: 24.07.2026 | G12: Solicitado 27.07.2026
... B17: FIS-MSC-2022-10/23-1627(EX) | C17: Edu | D17: Propal | E17: Claim Notice | F17: 13.08.2026 | G17: Por solicitar

Sheet General
A1: =-A1+'[1]2026'!$I$6 -> 0 | B1: Id | C1: Reference No | D1: Claim Handler | E1: CS Claim No | F1: Assured | G1: Opponent | H1: Vessel | I1: Place of Discharge | J1: Date of Discharge | K1: Surveyorco | L1: Voyage | M1: Status | N1: Summary | O1: Commodity | P1: Date of Loading | Q1: TB | R1: Fecha de Orden | S1: Fecha Update | T1: Participation | U1: Comentarios Reunión | V1: Itinerario MSC | W1: TT OFRECIDO | X1: TT REAL
A2: 117629.36 | B2: SOLICITADO | C2: PRE-FIS-ZIM-2025-01/27-3820 | D2: Emely Lambraño | E2: CS-2025-00865 | F2: Copefrut | G2: ZIM | H2: ZIM LUANDA | I2: Tianjin | J2: 03.01.2025 | K2: Teamhead | L2: 114W | M2: Falta Subro, AoR, harvest, survey report, liq. comparativa, DUS, IVV. | N2: temperatures | O2: Cherries | P2: 11.12.2024 | Q2: 04.01.2027
A3: 35760 | B3: 32547 | C3: PRE-FIS-YAN-2025-07/27-4117 | D3: Alejandra Peltier | E3: CS-2025-08640 | F3: Grin Export | G3: Yang Ming | H3: YM SUCCESS | I3: Jebel Ali | J3: 20.07.2025 | K3: Inchcape | L3: 182W | M3: Falta subro, AoR, harvest, DUS, IVV, Final report | N3: Delay | O3: Kiwis | P3: 16.05.2025 | Q3: 20.07.2027
B4: SOLICITADO | C4: PRE-FIS-WAN-2025-03/27-4029 | D4: Emely Lambraño | E4: CS-2025-02892 | F4: Agricom | G4: Wan Hai | H4: YM EXPRESS | I4: Busan | J4: 10.03.2025 | K4: Hyopsung | L4: 086W | M4: Falta Subro, AoR, harvest, Sales account, phyto, booking | N4: Delay & Inherent vice | O4: Blueberries | P4: 21.01.2025 | Q4: 10.03.2027
A5: 68928 | B5: SOLICITADO | C5: PRE-FIS-WAN-2025-03/27-3857 | D5: Emely Lambraño | E5: CS-2025-02939 | F5: RANCO | G5: Wan Hai | H5: YM EXPRESS | I5: Busan | J5: 09.03.2025 | K5: Hyopsung | L5: 086W | M5: Falta Subro, AoR | N5: Delay 16 DIAS / (Considerar ultimo reporte final subido a plataforma) | O5: Cherries | P5: 21.01.2025 | Q5: 10.03.2027 | R5: 10.07.2025
A6: 68928 | B6: SOLICITADO | C6: PRE-FIS-WAN-2025-03/27-3856 | D6: Emely Lambraño | E6: CS-2025-02934 | F6: RANCO | G6: Wan Hai | H6: YM EXPRESS | I6: Busan | J6: 09.03.2025 | K6: Hyopsung | L6: 086W | M6: Falta AoR | N6: Delay 16 DIAS / (considerar ultimo informe final cargado en plataforma) | O6: Cherries | P6: 21.01.2025 | Q6: 10.03.2027 | R6: 10.07.2025
A7: 43849.07 | B7: SOLICITADO | C7: PRE-FIS-COS-2025-01/27-3734 | D7: Alejandra Peltier | E7: CS-2025-04715 | F7: Prize | G7: Cosco | H7: YANTIAN | I7: Shanghai | J7: 03.01.2025 | K7: Teamhead | L7: 124W | M7: Falta AoR, harvest, origin, Invoice. Stuffing report, booking. | N7: temperature | O7: Cherries | P7: 09.12.2024 | Q7: 03.01.2027 | R7: 27.05.2025 | S7: 13.07.2026
B8: CALCULAR LOSS | C8: PRE-FIS-MAE-2025-07/27-4041 | D8: Emely Lambraño | E8: CS-2025-07601 | F8: Alempue | G8: Maersk | H8: SKAGEN MAERSK | I8: Cat Lai Port | J8: 06.07.2025 | K8: AIM Control | L8: 517W | M8: Falta subro, AoR, harvest, SMV O liqu. Comparativa. | N8: Delay | O8: Grapes | P8: 05.05.2025 | Q8: 06.07.2027 | R8: 17.09.2025
A9: 21357.05 | B9: SOLICITADO | C9: PRE-FIS-ONE-2025-04/27-3945 | D9: Alejandra Peltier | E9: CS-2025-04651 | F9: Prize | G9: ONE | H9: SEASPAN RAPTOR | I9: Keelung | J9: 21.04.2025 | K9: Teamhead | L9: 2501W | M9: Falta AoR, harvest | N9: Delay | O9: Plums | P9: 28.02.2025 | Q9: 21.04.2027 | R9: 18.07.2025 | S9: 13.07.2026
B10: SOLICITADO | C10: PRE-FIS-HLL-2025-03/27-3842 | D10: Emely Lambraño | E10: CS-2025-06244 | F10: Copefrut | G10: Hapag Lloyd | H10: SEASPAN BRIGHTNESS | I10: Hong Kong | J10: 13.03.2025 | K10: Teamhead | L10: 2451W | M10: Falta Subro, survey report, liquidación comparativa | N10: Delay | O10: Plums | P10: 14.02.2025 | Q10: 14.03.2027
A11: 12853 | B11: SOLICITADO | C11: PRE-FIS-MSC-2025-03/27-4286 | D11: Emely Lambraño | E11: CS-2025-03671 | F11: CFN | G11: MSC | H11: SEASPAN BRIGHTNESS | I11: Hong Kong | J11: 14.03.2025 | K11: Teamhead | L11: 2451W | M11: Falta subro, AoR, harvest, final report | N11: Temperature | O11: Grapes | P11: 14.02.2025 | Q11: 14.03.2027 | R11: 30.12.2025
A12: 41379.99 | B12: SOLICITADO | C12: PRE-FIS-HLL-2025-05/27-4100 | D12: Alejandra Peltier | E12: CS-2025-08603 | F12: Prize | G12: Hapag Lloyd | H12: SEASPAN BELIEF | I12: Mundra | J12: 27.06.2025 | K12: Zorro QC | L12: 2510W | M12: Falta subro, harvest, DUS, IVV, SR. | N12: Delay | O12: Walnut | P12: 27.04.2025 | Q12: 27.06.2027 | R12: 13.10.2025 | S12: 13.07.2026
B13: SOLICITADO | C13: PRE-FIS-SEA-2025-12/26-4064 | D13: Emely Lambraño | E13: CS-2025-09562 | F13: Family Farms | G13: Seaboard Marine | H13: SBD.GENESIS | I13: Philadelphia | J13: 21.12.2024 | K13: no surveyor involved | L13: SBD.GENESIS 16 | M13: Falta Subro, AoR, harvest certificate | N13: Delay (Allegedly 7 days of delay) | O13: Blueberries | P13: 03.12.2024 | Q13: 21.12.2026 | R13: 23.09.2025
A14: 10146.61 | B14: SOLICITADO | C14: PRE-FIS-HLL-2025-12/26-4068 | D14: Emely Lambraño | E14: CS-2025-00819 | F14: Jorge Schmidt | G14: Hapag Lloyd | H14: SANTOS EXPRESS | I14: London Gateway | J14: 22.12.2024 | K14: MMS | L14: 424N | M14: Falta subro, AoR, harvest certificate, final Report, destruction certificate and Invoice (If available) | N14: Delay (24 days) | O14: Avocados | P14: 14.11.2024 | Q14: 22.12.2026 | R14: 09.10.2025
A15: 5172.16 | B15: SOLICITADO | C15: PRE-FIS-CMA-2025-05/27-4005 | D15: Alejandra Peltier | E15: CS-2025-05381 | F15: FRUSAN | G15: CMA CGM | H15: SANTOS EXPRESS | I15: Rotterdam | J15: 08.05.2025 | K15: Fruit Inspection & Consultancy BV | L15: 0WCKIN1MA | M15: Falta AoR | N15: Temperature | O15: Pears | P15: 03.04.2025 | Q15: 08.05.2027 | S15: 08.04.2026
A16: 4445.98 | B16: SOLICITADO | C16: PRE-FIS-CMA-2025-05/27-4004 | D16: Alejandra Peltier | E16: CS-2025-05380 | F16: FRUSAN | G16: CMA CGM | H16: SANTOS EXPRESS | I16: Rotterdam | J16: 07.05.2025 | K16: Fruit Inspection & Consultancy BV | L16: 0WCKIN1MA | M16: Falta AoR | N16: Temperature | O16: Grapes | P16: 10.04.2025 | Q16: 06.05.2027 | S16: 08.04.2026
A17: 35560.58 | B17: SOLICITADO | C17: PRE-FIS-MAE-2025-05/27-4055 | D17: Emely Lambraño | E17: CS-2025-06247 | F17: Servicios Chilfresh | G17: Maersk | H17: SALLY MAERSK | I17: Cat Lai Port | J17: 31.05.2025 | K17: AIM Control | L17: 513W | M17: Falta subro, harvest, SMV | N17: Delay | O17: Grapes | P17: 08.04.2025 | Q17: 05.05.2027
A18: 12507.13 | B18: SOLICITADO | C18: PRE-FIS-MAE-2025-05/27-4142 | D18: Alejandra Peltier | E18: CS-2025-06883 | F18: Zepeda y Corral | G18: Maersk | H18: SALLY MAERSK | I18: Hong Kong | J18: 16.05.2025 | K18: Teamhead | L18: 513W | M18: Falta Final report, export Invoice, booking. | N18: Temperature | O18: Grapes | P18: 09.04.2025 | Q18: 16.05.2027 | R18: 11.11.2025 | S18: 22.07.2026
A19: 12016.96 | B19: SOLICITADO | C19: PRE-FIS-MAE-2025-05/27-4143 | D19: Alejandra Peltier | E19: CS-2025-06886 | F19: Zepeda y Corral | G19: Maersk | H19: SALLY MAERSK | I19: Hong Kong | J19: 16.05.2025 | K19: Teamhead | L19: 513W | M19: Falta Final report, export Invoice, booking. | N19: Temperature | O19: Grapes | P19: 09.04.2025 | Q19: 16.05.2027 | R19: 11.11.2025 | S19: 22.07.2026
A20: 13376.78 | B20: SOLICITADO | C20: PRE-FIS-MAE-2025-05/27-4144 | D20: Alejandra Peltier | E20: CS-2025-06884 | F20: Zepeda y Corral | G20: Maersk | H20: SALLY MAERSK | I20: Hong Kong | J20: 16.05.2025 | K20: Teamhead | L20: 513W | M20: Falta Final report, export Invoice, booking. | N20: Temperature | O20: Grapes | P20: 09.04.2025 | Q20: 16.05.2027 | R20: 11.11.2025 | S20: 22.07.2026
A21: 13440.03 | B21: SOLICITADO | C21: PRE-FIS-MAE-2025-05/27-4145 | D21: Alejandra Peltier | E21: CS-2025-06885 | F21: Zepeda y Corral | G21: Maersk | H21: SALLY MAERSK | I21: Hong Kong | J21: 16.05.2025 | K21: Teamhead | L21: 513W | M21: Falta Final report, export Invoice, booking. | N21: Temperature | O21: Grapes | P21: 09.04.2025 | Q21: 16.05.2027 | R21: 11.11.2025 | S21: 22.07.2026
A22: 56573.93 | B22: SOLICITADO | C22: PRE-FIS-MSC-2025-01/27-3998 | D22: Emely Lambraño | E22: CS-2025-02339 | F22: Duofrut | G22: MSC | H22: RIO DE JANEIRO EXPRESS | I22: Hong Kong | J22: 28.01.2025 | K22: Teamhead | L22: 2445W | M22: Falta subro, AoR, harvest, origin, SR, DUS, IVV. | N22: Closed Vent | O22: Cherries | P22: 06.01.2025 | Q22: 28.01.2027
B23: SOLICITADO | C23: PRE-FIS-HLL-2025-01/27-3834 | D23: Emely Lambraño | E23: CS-2025-01529 | F23: Magna | G23: Hapag Lloyd | H23: RIO DE JANEIRO EXPRESS | I23: Hong Kong | J23: 28.01.2025 | K23: Teamhead | L23: 2445W | M23: Falta Subro, AoR | N23: Temperature | O23: Cherries | P23: 05.01.2025 | Q23: 28.01.2027
A24: 45083.48 | B24: SOLICITADO | C24: PRE-FIS/FRU-ONE-2025-01/27-4108 | D24: Alejandra Peltier | E24: CS-2025-01422 | F24: FRUSAN | G24: ONE | H24: RIO DE JANEIRO EXPRESS | I24: Hong Kong | J24: 29.01.2025 | K24: Teamhead | L24: 2445W | M24: Falta AoR | N24: cut & run // pérdida de mercado delay 10 días, llega carta post año nuevo Chino | O24: Cherries | P24: 06.01.2025 | Q24: 29.01.2027 | S24: 08.04.2026 | U24: 06.08.2026 Según lo discutido, estos casos se manejarán por LWC, separados por naviera. Al momento de estar completos se traspasarían a Eduardo Rojas
A25: 50404.45 | B25: PRESENTAR | C25: PRE-FIS/FRU-HLL-2025-01/27-4109 | D25: Alejandra Peltier | E25: CS-2025-01423 | F25: FRUSAN | G25: Hapag Lloyd | H25: RIO DE JANEIRO EXPRESS | I25: Hong Kong | J25: 29.01.2025 | K25: Teamhead | L25: 2445W | M25: Ok | N25: cut & run // pérdida de mercado delay 10 días, llega carta post año nuevo Chino | O25: Cherries | P25: 06.01.2025 | Q25: 29.01.2027 | S25: 08.04.2026 | U25: 06.08.2026 Según lo discutido, estos casos se manejarán por LWC, separados por naviera. Al momento de estar completos se traspasarían a Eduardo Rojas
A26: 44186.92 | B26: PRESENTAR | C26: PRE-FIS/FRU-ONE-2025-01/27-4110 | D26: Alejandra Peltier | E26: CS-2025-01518 | F26: FRUSAN | G26: ONE | H26: RIO DE JANEIRO EXPRESS | I26: Hong Kong | J26: 28.01.2025 | K26: Teamhead | L26: 2445W | M26: Ok | N26: cut & run // pérdida de mercado delay 10 días, llega carta post año nuevo Chino | O26: Cherries | P26: 06.01.2025 | Q26: 29.01.2027 | S26: 08.04.2026 | U26: 06.08.2026 Según lo discutido, estos casos se manejarán por LWC, separados por naviera. Al momento de estar completos se traspasarían a Eduardo Rojas
A27: 24453.59 | B27: PRESENTAR | C27: PRE-FIS/FRU-HLL-2025-01/27-4111 | D27: Alejandra Peltier | E27: CS-2025-01519 | F27: FRUSAN | G27: Hapag Lloyd | H27: RIO DE JANEIRO EXPRESS | I27: Hong Kong | J27: 29.01.2025 | K27: Teamhead | L27: 2445W | M27: Falta stuffing, Fito. | N27: cut & run // pérdida de mercado delay 10 días, llega carta post año nuevo Chino | O27: Cherries | P27: 06.01.2025 | Q27: 29.01.2027 | S27: 08.04.2026 | U27: 06.08.2026 Según lo discutido, estos casos se manejarán por LWC, separados por naviera. Al momento de estar completos se traspasarían a Eduardo Rojas
A28: 59536.87 | B28: PRESENTAR | C28: PRE-FIS/FRU-HLL-2025-01/27-4112 | D28: Alejandra Peltier | E28: CS-2025-01520 | F28: FRUSAN | G28: Hapag LLoyd | H28: RIO DE JANEIRO EXPRESS | I28: Hong Kong | J28: 29.01.2025 | K28: Teamhead | L28: 2445W | M28: Ok | N28: cut & run // pérdida de mercado delay 10 días, llega carta post año nuevo Chino | O28: Cherries | P28: 06.01.2025 | Q28: 29.01.2027 | S28: 08.04.2026 | U28: 06.08.2026 Según lo discutido, estos casos se manejarán por LWC, separados por naviera. Al momento de estar completos se traspasarían a Eduardo Rojas
A29: 47094.15 | B29: SOLICITADO | C29: PRE-FIS/FRU-HLL-2025-01/27-4113 | D29: Alejandra Peltier | E29: CS-2025-01521 | F29: FRUSAN | G29: Hapag Lloyd | H29: RIO DE JANEIRO EXPRESS | I29: Hong Kong | J29: 28.01.2025 | K29: Teamhead | L29: 2445W | M29: Falta export Invoice, fito. | N29: cut & run // pérdida de mercado delay 10 días, llega carta post año nuevo Chino | O29: Cherries | P29: 06.01.2025 | Q29: 29.01.2027 | S29: 08.04.2026 | U29: 06.08.2026 Según lo discutido, estos casos se manejarán por LWC, separados por naviera. Al momento de estar completos se traspasarían a Eduardo Rojas
A30: 52091.22 | B30: PRESENTAR | C30: PRE-FIS/FRU-HLL-2025-01/27-4114 | D30: Alejandra Peltier | E30: CS-2025-01522 | F30: FRUSAN | G30: Hapag Lloyd | H30: RIO DE JANEIRO EXPRESS | I30: Hong Kong | J30: 28.01.2025 | K30: Teamhead | L30: 2445W | M30: Falta termógrafos. | N30: cut & run // pérdida de mercado delay 10 días, llega carta post año nuevo Chino | O30: Cherries | P30: 06.01.2025 | Q30: 28.01.2027 | S30: 08.04.2026 | U30: 06.08.2026 Según lo discutido, estos casos se manejarán por LWC, separados por naviera. Al momento de estar completos se traspasarían a Eduardo Rojas
A31: 362.04 | B31: SOLICITADO | C31: PRE-FIS/FRU-HLL-2025-01/27-4115 | D31: Alejandra Peltier | E31: CS-2025-01523 | F31: FRUSAN | G31: Hapag LLoyd | H31: RIO DE JANEIRO EXPRESS | I31: Hong Kong | J31: 29.01.2025 | K31: Teamhead | L31: 2445W | M31: Falta fito, export invoice. | N31: cut & run // pérdida de mercado delay 10 días, llega carta post año nuevo Chino | O31: Cherries | P31: 06.01.2025 | Q31: 29.01.2027 | S31: 08.04.2026 | U31: 06.08.2026 Según lo discutido, estos casos se manejarán por LWC, separados por naviera. Al momento de estar completos se traspasarían a Eduardo Rojas
A32: 35986.24 | B32: PRESENTAR | C32: PRE-FIS/FRU-HLL-2025-01/27-4116 | D32: Alejandra Peltier | E32: CS-2025-01524 | F32: FRUSAN | G32: Hapag Lloyd | H32: RIO DE JANEIRO EXPRESS | I32: Hong Kong | J32: 29.01.2025 | K32: Teamhead | L32: 2445W | M32: Falta export invoice, fito | N32: cut & run // pérdida de mercado delay 10 días, llega carta post año nuevo Chino | O32: Cherries | P32: 06.01.2025 | Q32: 29.01.2027 | S32: 08.04.2026 | U32: 06.08.2026 Según lo discutido, estos casos se manejarán por LWC, separados por naviera. Al momento de estar completos se traspasarían a Eduardo Rojas
B33: PRESENTAR | C33: PRE-FIS/FRU-HLL-2025-01/27-4139 | D33: Alejandra Peltier | E33: CS-2025-11038 | F33: FRUSAN | G33: Hapag LLoyd | H33: RIO DE JANEIRO EXPRESS | I33: Hong Kong | J33: 29.01.2025 | K33: no surveyor involved | L33: 2445W | M33: Ok | N33: cut & run // pérdida de mercado delay 10 días, llega carta post año nuevo Chino | O33: Cherries | P33: 06.01.2025 | Q33: 29.01.2027 | S33: 08.04.2026 | U33: 06.08.2026 Según lo discutido, estos casos se manejarán por LWC, separados por naviera. Al momento de estar completos se traspasarían a Eduardo Rojas
B34: SOLICITADO | C34: PRE-FIS/FRU-HLL-2025-01/27-4153 | D34: Alejandra Peltier | E34: CS-2025-11037 | F34: FRUSAN | G34: Hapag | H34: RIO DE JANEIRO EXPRESS | I34: Hong Kong | J34: 29.01.2025 | K34: no surveyor involved | L34: 2445W | M34: Falta AoR, tracking, QC o photos destino, termografos. | N34: cut & run // pérdida de mercado delay 10 días, llega carta post año nuevo Chino | O34: Cherries | P34: 06.01.2025 | Q34: 29.01.2027 | S34: 08.04.2026 | U34: 06.08.2026 Según lo discutido, estos casos se manejarán por LWC, separados por naviera. Al momento de estar completos se traspasarían a Eduardo Rojas
B35: SOLICITADO | C35: PRE-FIS-MAE-2025-11/26-4067 | D35: Emely Lambraño | E35: CS-2025-09564 | F35: Family Farms | G35: Maersk | H35: POLAR COLOMBIA | I35: Port Hueneme | J35: 08.11.2024 | K35: no surveyor involved | L35: 439N | M35: Falta subro, AoR, harvest certificate | N35: Delay (Allegedly 8 days of delay) | O35: Blueberries | P35: 12.10.2024 | Q35: 08.11.2026
B36: SOLICITADO | C36: PRE-FIS-MAE-2025-11/26-4063 | D36: Emely Lambraño | E36: CS-2025-09557 | F36: Family Farms | G36: Maersk | H36: POLAR COLOMBIA | I36: Philadelphia | J36: 05.11.2024 | K36: no surveyor involved | L36: 439N | M36: Falta subro, AoR, harvest certificate | N36: Delay (Allegedly 11 days of delay) | O36: Blueberries | P36: 12.10.2024 | Q36: 05.11.2026
B37: SOLICITADO | C37: PRE-FIS-MAE-2025-02/27-3462 | D37: Emely Lambraño | E37: CS-2025-02983 | F37: Propal | G37: Maersk | H37: POLAR COLOMBIA | I37: Sydney | J37: 13.02.2025 | K37: McLarens | L37: 451N | M37: Falta Subro, AoR, Destruction Certificate | N37: CA | O37: Avocados | Q37: 13.02.2027
B38: SOLICITADO | C38: PRE-FIS-MAE-2025-12/26-4049 | D38: Emely Lambraño | E38: CS-2025-00492 | F38: Family Farms | G38: Maersk | H38: POLAR ARGENTINA | I38: Philadelphia | J38: 02.12.2024 | K38: PCCC | L38: 441N | M38: Falta subro, AoR, harvest certificate | N38: Delay (Allegedly 21+ days of delay) | O38: Blueberries | P38: 26.10.2024 | Q38: 02.12.2026 | R38: 23.09.2025
B39: SOLICITADO | C39: PRE-FIS-MAE-2025-01/27-3376 | D39: Emely Lambraño | E39: CS-2025-09086 | F39: Family Farms | G39: Maersk | H39: POLAR ARGENTINA | I39: Algeciras | J39: 22.01.2025 | K39: Eurovet | L39: 449n | M39: Falta subro, AoR, harvest certificate, sales acc, SMV | N39: Delay (14 days) | O39: Blueberries | P39: 21.12.2024 | Q39: 22.01.2027
A40: 17723.99 | B40: SOLICITADO | C40: PRE-FIS-MAE-2025-01/27-3448 | D40: Emely Lambraño | E40: CS-2025-00900 | F40: Agualima | G40: Maersk | H40: POLAR ARGENTINA | I40: Philadelphia | J40: 13.01.2025 | K40: PCCC | L40: 445N | M40: Falta Subro, AoR, harvest cert. Origin certificate, phyto | N40: Delay 35 días | O40: Blueberries | P40: 23.11.2024 | Q40: 13.01.2027
...

Sheet Revisar
A1: 0 | B1: Id | C1: Reference No | D1: Claim Handler | E1: CS Claim No | F1: Assured | G1: Opponent | H1: Vessel | I1: Place of Discharge | J1: Date of Discharge | K1: Surveyorco | L1: Voyage | M1: Status | N1: Summary | O1: Commodity | P1: Date of Loading | Q1: TB | R1: Fecha de Orden

Sheet Presentar
A1: Claim amount | B1: Fecha de Traspaso | C1: Reference No | D1: Claim Handler | E1: CS Claim No | F1: Assured | G1: Opponent | H1: Vessel | I1: Place of Discharge | J1: Date of Discharge | K1: Surveyorco | L1: Voyage | M1: Status | N1: Summary | O1: Commodity | P1: Date of Loading | Q1: TB | R1: Comments
A2: 4220.76 | B2: 20.08.2026 | C2: PRE-FIS-MAE-2025-05/27-4148 | D2: Alejandra Peltier | E2: CS-2025-11723 | F2: Lo Garces | G2: Maersk | H2: MAERSK BENGUELA | I2: London Gateway | J2: 11.05.2025 | K2: no surveyor involved | L2: 511N | M2: Ok (cliente no cuenta con termógrafos) | O2: Plums | P2: 19.03.2025 | Q2: 11.05.2027 | R2: 23.03.2026 | S2: 07.04.2026
A3: 5400 | B3: 20.08.2026 | C3: PRE-FIS-MSC-2025-02/27-4147 | D3: Alejandra Peltier | E3: CS-2025-11720 | F3: Lo Garces | G3: MSC | H3: MSC BRITTANY | I3: London Gateway | J3: 17.02.2025 | K3: no surveyor involved | L3: NX502R | M3: Ok (cliente no cuenta con termógrafos) | N3: Delay | O3: Nectarines | P3: 09.01.2025 | Q3: 17.02.2027 | R3: 23.03.2026 | S3: 07.04.2026
A4: 52883.43 | B4: 20.08.2026 | C4: PRE-FIS-MSC-2026-01/28-4458 | D4: Alejandra Peltier | E4: CS-2026-01462 | F4: FRUSAN | G4: MSC | H4: MSC LEIGH | I4: Shanghai | J4: 14.01.2026 | K4: Teamhead | L4: XA549A | M4: Falta Harvest, SR | N4: Temperature | O4: Cherries | P4: 19.12.2025 | Q4: 14.01.2028 | R4: 15.04.2026
A5: 37076.48 | B5: 20.08.2026 | C5: PRE-FIS-ONE-2026-02/28-4571 | D5: Alejandra Peltier | E5: CS-2026-02369 | F5: FRUSAN | G5: ONE | H5: BUENOS AIRES EXPRESS | I5: Shanghai | J5: 19.02.2026 | K5: Teamhead | L5: 2545W | M5: Falta harvest certificate, survey report, claim notice. | N5: Delay (16 days) | O5: Blueberries | P5: 28.12.2025 | Q5: 19.02.2028 | R5: 29.04.2026 | S5: 06.07.2026
A6: 53664.68 | B6: 20.08.2026 | C6: PRE-FIS/AGR-MSC-2026-03/27-4731 | D6: Emely Lambraño | E6: DIRECTO | F6: Agricom | G6: MSC | H6: MSC CASSANDRE | I6: Los Angeles | J6: 11.03.2026 | K6: PCCC | L6: NX607R | M6: Falta LoA, AoR, harvest certificate. (en gestión) | N6: Temperature | O6: Plums | P6: 15.02.2026 | Q6: 11.03.2028 | R6: 10.08.2026

Sheet Traspasados
C1: Reference No | D1: Claim Handler | E1: CS Claim No | F1: Assured | G1: Opponent | H1: Vessel | I1: Place of Discharge | J1: Date of Discharge | K1: Surveyorcomp | L1: Voyage | M1: Status | N1: Summary | O1: Commodity | P1: Date of Loading | Q1: TB | R1: Participation | S1: Reunión comentarios
A2: 35131 | B2: TRASPASADO | C2: PRE-FIS-TKS-2023-01/24-2580 | D2: Camila Sanhueza | E2: CS-2022-12584 | F2: Gidding Cerasus S.A. | G2: Turkish Airlines | I2: Phnom Penh | J2: 02.01.2022 | K2: Other | L2: TK0900/21 TK0778/23 | M2: Falta claim notice | N2: DELAY 11 DIAS + TEMPS | O2: Cherries | P2: 20.12.2021 | Q2: 02.01.2024
A3: 29557.86 | B3: TRASPASADO | C3: PRE-FIS-YAN-2023-03/25-2667 | D3: Nicolas Aravena | E3: CS-2023-04197 | F3: FRUSAN | G3: Yang Ming | H3: (NOT IN LIST) | I3: Shanghai | J3: 05.03.2023 | K3: Teamhead | L3: W013 | M3: Falta Harvest, DUS, IVV, STUFFING, PHYTO, ORIGIN, BOOKING | N3: CA | O3: PLUMS | P3: 04.02.2023 | Q3: 05.03.2025
A4: 50927.79 | B4: TRASPASADO/SR | C4: PRE-FIS-COS-2023-01/25-2562 | D4: Victor Vilches | E4: CS-2023-04357 | F4: Copefrut | G4: COSCO | H4: (NOT IN LIST) | I4: Shanghai | J4: 14.01.2023 | K4: Teamhead | L4: 049W | M4: Falta , claim notice, , harvest, SR | N4: VENTILATION | O4: Cherries | P4: 18.12.2022 | Q4: 14.01.2025
A5: 43143.51 | B5: TRASPASADO | C5: PRE-FIS-COS-2023-01/25-2563 | D5: Victor Vilches | E5: CS-2023-04359 | F5: Copefrut | G5: COSCO | H5: (NOT IN LIST) | I5: Shanghai | J5: 14.01.2023 | K5: Teamhead | L5: 049W | M5: Falta , claim notice harvest, | N5: TEMPERATURE | O5: Cherries | P5: 17.12.2022 | Q5: 14.01.2025 | S5: 15.06.2023 Preguntarle a Kelly comentarios. Si es origen, se cierra
A6: 3360 | B6: TRASPASADO | C6: PRE-FIS-CC-2023-03/25-2729 | D6: Camila Sanhueza | E6: CS-2023-04250 | F6: Agricom | G6: Cool Carriers | H6: (NOT IN LIST) | I6: Gloucester City | J6: 05.03.2023 | K6: PCCC | L6: EC140 | M6: ok | N6: CONTAMINATION | O6: Grapes | P6: 20.02.2023 | Q6: 05.03.2025
A7: 12181.25 | B7: PRESENTAR | C7: PRE-FIS-AFR-2024-12/25-3133 | D7: Isidora Martinez | E7: CS-2024-02031 | F7: AMS EUROPEAN | G7: Air France | H7: AIRFREIGHT | I7: Charles de Gaulle Airport | J7: 09.12.2023 | K7: Other | L7: AF0401 | M7: Falta harvest, stuffing, booking | N7: Delay 2 dias | O7: CHERRIES | P7: 08.12.2023 | Q7: 09.12.2025
A8: 25340.46 | B8: PRESENTAR | C8: PRE-FIS-QAW-2024-11/25-3042 | D8: Thomas Chatterton | E8: CS-2024-01396 | F8: Agricom | G8: Qatar Airways | H8: AIRFREIGHT | I8: Mumbai | J8: 30.11.2023 | K8: Intertek, IND | L8: QR8307 | M8: ok | N8: Variaciones de temperatura durante tránsito y al embarque. | O8: Cherries | P8: 25.11.2023 | Q8: 30.11.2025
A9: 273127 | B9: TRASPASADO | C9: PRE-FIS-ONE-2023-02/25-2717 | D9: Isidora Martinez | E9: CS-2023-04245 | F9: Agricom | G9: ONE | H9: AKADIMOS | I9: Hong Kong | J9: 19.02.2023 | K9: Teamhead | L9: 2250W | M9: Falta Harvest, DUS, IVV | N9: TEMPERATURA | O9: Cherries | P9: 25.01.2023 | Q9: 19.02.2025
A10: 3254.75 | B10: TRASPASADO | C10: PRE-FIS-CMA-2023-01/24-2861 | D10: Camila Sanhueza | E10: CS-2023-08134 | F10: Itacu Corporation ltda. | G10: CMA CGM | H10: ALEXIS | I10: Catania | J10: 17.01.2023 | K10: Spolidoro | L10: 0DVEEN1MA | M10: ok | N10: Temperature. Dos interrupciones importantes de temperatura | O10: BANANAS | P10: 29.12.2022 | Q10: 17.01.2024
A11: 12697.73 | B11: TRASPASADO | C11: PRE-FIS-CMA-2023-03/24-2749 | D11: Isidora Martinez | E11: CS-2023-04345 | F11: Itacu Corporation ltda. | G11: CMA CGM | H11: ALEXIS | I11: Catania | J11: 13.03.2023 | K11: Spolidoro | L11: 0DVEUN1MA | M11: ok | N11: TEMPERATURE | O11: BANANAS | P11: 23.02.2023 | Q11: 13.03.2024
A12: 38660.49 | B12: TRASPASADO | C12: PRE-FIS-CMA-2024-01/24-2884 | D12: Camila Sanhueza | E12: CS-2023-08133 | F12: Itacu Corporation ltda. | G12: CMA CGM | H12: ALEXIS | I12: Catania | J12: 17.01.2023 | K12: Spolidoro | L12: 0DVEEN1MA | M12: ok | N12: Temperature issues | O12: Bananas | P12: 29.12.2022 | Q12: 17.01.2024
A13: 6407.8 | B13: PRESENTAR | C13: PRE-FIS-ONE-2024-01/26-2963 | D13: Thomas Chatterton | E13: CS-2024-01483 | F13: Agricola Rapel | G13: ONE | H13: ALGOL | I13: Kaohsiung | J13: 04.01.2024 | K13: Teamhead | L13: 23023N | M13: OK | N13: DELAY 14 DIAS | O13: GRAPES | P13: 14.11.2023 | Q13: 04.01.2026
A14: 54886.53 | B14: TRASPASADO | C14: PRE-FIS-HLL-2023-01/25-2663 | D14: Barbara Choque | E14: CS-2023-04186 | F14: FRUSAN | G14: Hapag Lloyd | H14: AMALTHEA | I14: Nansha | J14: 09.01.2023 | K14: Teamhead | L14: 0001W | M14: Falta factura exportación, DUS, IVV, Booking, Stuffing Report | N14: Temperature issues | O14: Cherries | P14: 17.12.2022 | Q14: 09.01.2025
A15: 100556.87 | B15: TRASPASADO | C15: PRE-FIS-EVG-2023-01/25-2507(EX) | D15: Barbara Choque | E15: CS-2023-04664 | F15: Prize | G15: Evergreen | H15: ANTHEA Y | I15: Keelung | J15: 20.01.2023 | K15: Teamhead | M15: ok | N15: TEMPERATURA | O15: Cherries | P15: 21.12.2022 | Q15: 20.01.2025
A16: 26020.99 | B16: TRASPASADO | C16: FIS-HAM-2022-01/23-1370 | D16: Isidora Martinez | E16: CS-2021-50556 | F16: Copefrut | G16: Hamburg Süd | H16: AOTEA MAERSK | I16: Hong Kong | J16: 07.01.2021 | K16: Teamhead | L16: 049W | M16: Falta HC. | N16: TEMP ( Se sugiere exhibición) | O16: Cherries | P16: 16.12.2020 | Q16: 44933
A17: 64755.59 | B17: TRASPASADO | C17: PRE-FIS-COS-2022-10/23-2246 | D17: Isidora Martinez | E17: CS-2022-12238 | F17: Jealous Fruits | G17: COSCO | H17: APL LE HAVRE | I17: Vancouver/Shanghai | J17: 04.10.2022 | K17: Teamhead | L17: 0TN7CN1MA | M17: Falta reporte de calidad | N17: Delay 11 days, as per BL -0,5°C and thermograph shows 2,1°C and 3,1°C | O17: Cherries | P17: 10.09.2022 | Q17: 45203
A18: 46276.19 | B18: TRASPASADO | C18: PRE-FIS-COS-2022-10/23-2245 | D18: Isidora Martinez | E18: CS-2022-12237 | F18: Jealous Fruits | G18: COSCO | H18: APL LE HAVRE | I18: Vancouver/Shanghai | J18: 04.10.2022 | K18: Teamhead | L18: OTN7CN1MA | M18: Falta reporte de calidad | N18: Delay 11 days | O18: Cherries | P18: 10.09.2022 | Q18: 45203
A19: 101131.87 | B19: TRASPASADO | C19: FIS-HLL-2022-01/23-2004 | D19: Isidora Martinez | E19: CS-2022-02353 | F19: Asica Farms SAC | G19: Hapag Lloyd | H19: AS PATRIA | I19: Malaga | J19: 13.01.2022 | K19: Eurovet | L19: 2139W | M19: Falta BL Máster | N19: TEMPERATURA | O19: Blueberries | P19: 16.12.2021 | Q19: 44939 | S19: Se continua con solicitud de documentos. Se traspasa a Isi para avance.
A20: 87181.04 | B20: TRASPASADO | C20: PRE-FIS-CMA-2022-02/23-2018 | D20: Isidora Martinez | E20: CS-2022-05388 | F20: Asica Farms SAC | G20: CMA CGM | H20: AS PATRIA | I20: Paita / | J20: 16.02.2022 | K20: Eurovet | L20: 0VF7CN1MA | M20: ok | N20: Delay 15 días | O20: Mangoes | P20: 12.01.2022 | Q20: 44973
A21: 23940 | B21: TRASPASADO | C21: PRE-FIS-CMA-2022-03/23-2149 | D21: Isidora Martinez | E21: CS-2022-05302 | F21: Frusan Agro | G21: CMA CGM | H21: AS PATRIA | I21: Paita-Hai Phòng | J21: 16.03.2022 | L21: 0VF7CN1MA | M21: Factura comercial, packing list, notificación naviera, reporte consolidado con temperaturas | N21: Delay TT 68 días. | O21: Grapes | P21: 12.01.2022 | Q21: 45001 | S21: 02-02-2023 - Para solicitud de TE, a medida que lleguen docus se irán proporcionando
A22: 65365.5 | B22: TRASPASADO | C22: PRE-FIS-STD-2023-11/24-2366 | D22: Camila Sanhueza | E22: CS-2022-12648 | F22: Agualima | G22: Seatrade | H22: ATLANTIC REEFER | I22: Vlissingen | J22: 01.11.2022 | K22: Fruit Inspection & Consultancy BV | L22: CS | M22: ok | N22: Alza de temperatura | O22: Blueberries | P22: 16.10.2022 | Q22: 01.11.2024
A23: 41367.75 | B23: PRESENTAR | C23: PRE-FIS-TRS-2024-02/25-2918 | D23: Nicolás Aravena | E23: CS-2023-04154 | F23: Geofrut | G23: Trans Global | H23: AUTUMN STREAM | I23: Wilmington | J23: 14.02.2023 | K23: PCCC | L23: USEC-04 | M23: ok | N23: Temperature | O23: Grapes | P23: 26.01.2023 | Q23: 14.02.2025 | R23: Innspector indica que necesitan de otros antecedentes para continuar con el caso, de lo contrario no pueden emitir reporte. Hemos focalizado solicitud con Susane.- Inspector responde que aun clarificando la venta (por la cantidad de cajas del embarque y clarificando los termógrafos correspondientes al caso, no se justificaría el daño encontrado en la carga (más bien de origen).- | S23: Se traspasa a Judicial pq no se consigue TE
A24: 17802.23 | B24: TRASPASADO | C24: PRE-FIS-CMA-2023-04/25-2658 | D24: Nicolas Aravena | E24: CS-2023-05904 | F24: David del Curto | G24: CMA CGM | H24: BALLENITA | I24: Leghorn | J24: 11.04.2023 | K24: Spolidoro | M24: Falta DUS, IVV | N24: TEMPERATURAS | O24: Pears | P24: 25.02.2023 | Q24: 11.04.2025
A25: 58288.15 | B25: TRASPASADO | C25: PRE-FIS-CMA-2023-05/25-2788 | D25: Isidora Martinez | E25: CS-2023-10246 | F25: FRUSAN | G25: CMA CGM | H25: BALLENITA | I25: Leghorn | J25: 21.05.2023 | K25: Spolidoro | L25: 0LI0WN1MA | M25: Falta Harvest, Booking (todos los contenedores), Origen (todos los contenedores) DUS, IVV (todos los contenedores) | N25: Temperature issues | O25: PEARS | P25: 07.04.2023 | Q25: 21.05.2025
A26: 16084.04 | B26: TRASPASADO | C26: FIS-HLL-2022-03/23-1465(EX) | D26: Nicolas Aravena | E26: cs2021-58170 | F26: Subsole | G26: Hapag Lloyd | H26: BOMAR JULIANA | I26: London Gateway | J26: 02.03.2021 | K26: Fresh Produce | L26: 0053N | M26: Falta liquidación 1. 27.05.2022 (LB) 596 boxes were dumped (11.324 GBP), DUS | N26: Low temperature abuse resulting in chill damage to the grapes | O26: Grapes | P26: 28.01.2021 | Q26: 44987
A27: 20631.45 | B27: TRASPASADO | C27: FIS-CMA-2022-02/23-1405(EX) | D27: Nicolas Aravena | E27: CS-2021-51124 | F27: ROVEG | G27: CMA CGM | H27: BOMAR JULIANA | I27: Rotterdam | J27: 25.02.2021 | K27: Fruit Inspection & Consultancy BV | L27: Falta SR. | M27: Temperatura anormal | O27: 25.02.2023
A28: 176594.68 | B28: TRASPASADO | C28: PRE-FIS-UCC-2023-03/25-2727 | D28: Barbara Choque | E28: CS-2023-05449 | F28: Verfrut | H28: BOMAR PRAIA | I28: Algeciras | K28: Eurovet | L28: 0LI0GN1MA | M28: Falta Tracking, DUS IVV | N28: TEMPERATURA | O28: PEARS | P28: 11.02.2023 | Q28: 07.03.2023
A29: 71025.24 | B29: PRESENTAR | C29: PRE-FIS-MSC-2024-02/26-3077 | D29: Nicolas Aravena | E29: CS-2024-02433 | F29: Verfrut | G29: MSC | H29: BUENAVENTURA EXPRESS | I29: Hong Kong | J29: 21.02.2024 | K29: Teamhead | L29: 2349W | M29: Falta SR. | N29: Temperature | O29: Nectarines | P29: 27.01.2024 | Q29: 21.02.2026
A30: 76377.6 | B30: PRESENTAR | C30: PRE-FIS-HLL-2024-03/26-3093 | D30: Barbara Choque | E30: CS-2024-02452 | F30: RANCO | G30: Hapag Lloyd | H30: BUENAVENTURA EXPRESS | I30: Busan | J30: 01.03.2024 | K30: Hyopsung | L30: 2349W | M30: ok | N30: Condicion de origen exacerbada por temperatura | O30: Cherries | P30: 28.01.2024 | Q30: 01.03.2026 | S30: 19.06.2024 (LB) EX una vez listo, sin presentar reporte
A31: 69147.6 | B31: PRESENTAR | C31: PRE-FIS-HLL-2024-03/26-3094 | D31: Barbara Choque | E31: CS-2024-02424 | F31: RANCO | G31: Hapag Lloyd | H31: BUENAVENTURA EXPRESS | I31: Busan | J31: 01.03.2024 | K31: Hyopsung | L31: 2349W | M31: ok | N31: Condicion de origen exacerbada por temperatura | O31: Cherries | P31: 28.01.2024 | Q31: 01.03.2026 | S31: 19.06.2024 (LB) EX una vez listo, sin presentar reporte
A32: 66000 | B32: PRESENTAR | C32: PRE-FIS-MSC-2024-06/26-3192 | D32: Barbara Choque | E32: CS-2024-07006 | F32: Verfrut | G32: MSC | H32: BUENAVENTURA EXPRESS | I32: Surabaya | J32: 28.06.2024 | K32: Carsurin | L32: 2410W | M32: Falta AoR | N32: DELAY 22 DIAS // falla cold treatment | O32: GRAPES | P32: 24.04.2024 | Q32: 28.06.2026
A33: 23716.14 | B33: PRESENTAR | C33: PRE-FIS-CMA-2023-05/25-2829 | D33: Barbara Choque | E33: CS-2023-07076 | F33: FRUSAN | G33: CMA CGM | H33: BUENOS AIRES EXPRESS | I33: Rotterdam | J33: 24.05.2023 | K33: Fruit Inspection & Consultancy BV | L33: 0WCEKN1MA | M33: Falta Origen, Booking, DUS, IVV, Stuffing, SR. | N33: Inspecto indica 10% relacionado a transporte y el resto origen. Evidente problema de temperatura en viaje. | O33: Apples | P33: 27.04.2023 | Q33: 24.05.2025 | S33: 26.09.2024 NO USAR REPORTE
A34: 35543.75 | B34: PRESENTAR | C34: PRE-FIS-HLL-2024-03/26-3284 | D34: Victor Vilches | E34: CS-2024-08131 | F34: FRUSAN | G34: Hapag Lloyd | H34: BUENOS AIRES EXPRESS | I34: Hong Kong | J34: 14.03.2024 | K34: no surveyor involved | L34: 2352W | M34: Falta Claim notice, DUS, IVV | N34: DELAY 6 DIAS POL/ pérdida de mercado | O34: Plums | P34: 21.02.2024 | Q34: 14.03.2026
A35: 37008 | B35: PRESENTAR | C35: PRE-FIS-HLL-2024-03/26-3206 | D35: Victor Vilches | E35: CS-2024-07080 | F35: FRUSAN | G35: Hapag Lloyd | H35: BUENOS AIRES EXPRESS | I35: Hong Kong | J35: 14.03.2024 | K35: no surveyor involved | L35: 2352W | M35: Falta sales account, claim notice, DUS IVV | N35: Loss in Market / delay // 6 dias de demora // Frusan indica que son 76 contenedores los involucrados,con una pérdida de 350.000USD | O35: Plums | P35: 21.02.2024 | Q35: 14.03.2026 | S35: 26.09.2024 Se tiene que conseguir la notificación, sin notificacion se debe volver a revisarse.
A36: 24150.86 | B36: PRESENTAR | C36: PRE-FIS-HLL-2024-03/26-3282 | D36: Victor Vilches | E36: CS-2024-08129 | F36: FRUSAN | G36: Hapag Lloyd | H36: BUENOS AIRES EXPRESS | I36: Hong Kong | J36: 14.03.2024 | K36: no surveyor involved | L36: 2352W | M36: Falta AoR, Booking, Claim notice, DUS, IVV | N36: DELAY 6 DIAS POL/ pérdida de mercado | O36: Plums | P36: 21.02.2024 | Q36: 14.03.2026
A37: 35994.11 | B37: PRESENTAR | C37: PRE-FIS-HLL-2024-03/26-3283 | D37: Victor Vilches | E37: CS-2024-08130 | F37: FRUSAN | G37: Hapag Lloyd | H37: BUENOS AIRES EXPRESS | I37: Hong Kong | J37: 24.03.2024 | K37: no surveyor involved | L37: 2352W | M37: Falta AoR, Booking, Claim notice, Packing, DUS, IVV, | N37: DELAY 6 DIAS POL/ pérdida de mercado | O37: Plums | P37: 21.02.2024 | Q37: 14.03.2026
A38: 39970.97 | B38: PRESENTAR | C38: PRE-FIS-HLL-2024-03/26-3285 | D38: Victor Vilches | E38: CS-2024-08132 | F38: FRUSAN | G38: Hapag Lloyd | H38: BUENOS AIRES EXPRESS | I38: Hong Kong | J38: 14.03.2024 | K38: no surveyor involved | L38: 2352W | M38: Falta AoR, Booking, Claim notice, DUS, IVV, SR (no surveyor involved) | N38: DELAY 6 DIAS POL/ pérdida de mercado | O38: Plums | P38: 21.02.2024 | Q38: 14.03.2026
A39: 30639.19 | B39: PRESENTAR | C39: PRE-FIS-HLL-2024-03/26-3287 | D39: Victor Vilches | E39: CS-2024-08133 | F39: FRUSAN | G39: Hapag Lloyd | H39: BUENOS AIRES EXPRESS | I39: Hong Kong | J39: 28.03.2024 | K39: no surveyor involved | L39: 2352W | M39: Falta Booking, Claim notice, Packing, DUS, IVV | N39: DELAY 6 DIAS POL/ pérdida de mercado | O39: Plums | P39: 21.02.2024 | Q39: 14.03.2026
A40: 36715.66 | B40: PRESENTAR | C40: PRE-FIS-HLL-2024-03/26-3289 | D40: Victor Vilches | E40: CS-2024-08134 | F40: FRUSAN | G40: Hapag Lloyd | H40: BUENOS AIRES EXPRESS | I40: Hong Kong | J40: 14.03.2024 | K40: no surveyor involved | L40: 2352W | M40: Falta AoR, Claim notice, DUS, IVV, | N40: DELAY 6 DIAS POL/ pérdida de mercado | O40: Plums | P40: 21.02.2024 | Q40: 14.03.2026
...

Sheet Revision Ale
